[2025-03-27T17:29:33.737+0000] {taskinstance.py:1956} INFO - Dependencies all met for dep_context=non-requeueable deps ti=<TaskInstance: workflow.Load scheduled__2024-03-08T00:00:00+00:00 [queued]>
[2025-03-27T17:29:33.759+0000] {taskinstance.py:1956} INFO - Dependencies all met for dep_context=requeueable deps ti=<TaskInstance: workflow.Load scheduled__2024-03-08T00:00:00+00:00 [queued]>
[2025-03-27T17:29:33.760+0000] {taskinstance.py:2170} INFO - Starting attempt 1 of 6
[2025-03-27T17:29:33.896+0000] {taskinstance.py:2191} INFO - Executing <Task(BashOperator): Load> on 2024-03-08 00:00:00+00:00
[2025-03-27T17:29:33.922+0000] {standard_task_runner.py:60} INFO - Started process 1728 to run task
[2025-03-27T17:29:33.929+0000] {standard_task_runner.py:87} INFO - Running: ['***', 'tasks', 'run', 'workflow', 'Load', 'scheduled__2024-03-08T00:00:00+00:00', '--job-id', '132', '--raw', '--subdir', 'DAGS_FOLDER/workflow.py', '--cfg-path', '/tmp/tmpwaso_kh8']
[2025-03-27T17:29:33.935+0000] {standard_task_runner.py:88} INFO - Job 132: Subtask Load
[2025-03-27T17:29:34.096+0000] {task_command.py:423} INFO - Running <TaskInstance: workflow.Load scheduled__2024-03-08T00:00:00+00:00 [running]> on host 77747a310b55
[2025-03-27T17:29:34.237+0000] {local_task_job_runner.py:121} ERROR - Received SIGTERM. Terminating subprocesses
[2025-03-27T17:29:34.257+0000] {process_utils.py:131} INFO - Sending 15 to group 1728. PIDs of all processes in the group: [1728]
[2025-03-27T17:29:34.258+0000] {process_utils.py:86} INFO - Sending the signal 15 to group 1728
[2025-03-27T17:29:34.261+0000] {taskinstance.py:2450} ERROR - Received SIGTERM. Terminating subprocesses.
[2025-03-27T17:29:34.263+0000] {subprocess.py:104} INFO - Sending SIGTERM signal to process group
[2025-03-27T17:29:34.289+0000] {taskinstance.py:2698} ERROR - Task failed with exception
Traceback (most recent call last):
  File "/home/airflow/.local/lib/python3.8/site-packages/airflow/models/taskinstance.py", line 2334, in _run_raw_task
    self._execute_task_with_callbacks(context, test_mode, session=session)
  File "/home/airflow/.local/lib/python3.8/site-packages/airflow/models/taskinstance.py", line 2469, in _execute_task_with_callbacks
    RenderedTaskInstanceFields.write(rtif)
  File "/home/airflow/.local/lib/python3.8/site-packages/airflow/utils/session.py", line 79, in wrapper
    return func(*args, session=session, **kwargs)
  File "/home/airflow/.local/lib/python3.8/site-packages/airflow/utils/retries.py", line 91, in wrapped_function
    for attempt in run_with_db_retries(max_retries=retries, logger=logger, **retry_kwargs):
  File "/home/airflow/.local/lib/python3.8/site-packages/tenacity/__init__.py", line 347, in __iter__
    do = self.iter(retry_state=retry_state)
  File "/home/airflow/.local/lib/python3.8/site-packages/tenacity/__init__.py", line 314, in iter
    return fut.result()
  File "/usr/local/lib/python3.8/concurrent/futures/_base.py", line 437, in result
    return self.__get_result()
  File "/usr/local/lib/python3.8/concurrent/futures/_base.py", line 389, in __get_result
    raise self._exception
  File "/home/airflow/.local/lib/python3.8/site-packages/airflow/utils/retries.py", line 100, in wrapped_function
    return func(*args, **kwargs)
  File "/home/airflow/.local/lib/python3.8/site-packages/airflow/models/renderedtifields.py", line 192, in write
    session.merge(self)
  File "/home/airflow/.local/lib/python3.8/site-packages/sqlalchemy/orm/session.py", line 3056, in merge
    return self._merge(
  File "/home/airflow/.local/lib/python3.8/site-packages/sqlalchemy/orm/session.py", line 3136, in _merge
    merged = self.get(
  File "/home/airflow/.local/lib/python3.8/site-packages/sqlalchemy/orm/session.py", line 2853, in get
    return self._get_impl(
  File "/home/airflow/.local/lib/python3.8/site-packages/sqlalchemy/orm/session.py", line 2975, in _get_impl
    return db_load_fn(
  File "/home/airflow/.local/lib/python3.8/site-packages/sqlalchemy/orm/loading.py", line 530, in load_on_pk_identity
    session.execute(
  File "/home/airflow/.local/lib/python3.8/site-packages/sqlalchemy/orm/session.py", line 1717, in execute
    result = conn._execute_20(statement, params or {}, execution_options)
  File "/home/airflow/.local/lib/python3.8/site-packages/sqlalchemy/engine/base.py", line 1710, in _execute_20
    return meth(self, args_10style, kwargs_10style, execution_options)
  File "/home/airflow/.local/lib/python3.8/site-packages/sqlalchemy/sql/elements.py", line 334, in _execute_on_connection
    return connection._execute_clauseelement(
  File "/home/airflow/.local/lib/python3.8/site-packages/sqlalchemy/engine/base.py", line 1577, in _execute_clauseelement
    ret = self._execute_context(
  File "/home/airflow/.local/lib/python3.8/site-packages/sqlalchemy/engine/base.py", line 1953, in _execute_context
    self._handle_dbapi_exception(
  File "/home/airflow/.local/lib/python3.8/site-packages/sqlalchemy/engine/base.py", line 2138, in _handle_dbapi_exception
    util.raise_(exc_info[1], with_traceback=exc_info[2])
  File "/home/airflow/.local/lib/python3.8/site-packages/sqlalchemy/util/compat.py", line 211, in raise_
    raise exception
  File "/home/airflow/.local/lib/python3.8/site-packages/sqlalchemy/engine/base.py", line 1910, in _execute_context
    self.dialect.do_execute(
  File "/home/airflow/.local/lib/python3.8/site-packages/sqlalchemy/engine/default.py", line 736, in do_execute
    cursor.execute(statement, parameters)
  File "/usr/local/lib/python3.8/encodings/utf_8.py", line 15, in decode
    def decode(input, errors='strict'):
  File "/home/airflow/.local/lib/python3.8/site-packages/airflow/models/taskinstance.py", line 2452, in signal_handler
    raise AirflowException("Task received SIGTERM signal")
airflow.exceptions.AirflowException: Task received SIGTERM signal
[2025-03-27T17:29:34.314+0000] {taskinstance.py:1138} INFO - Marking task as UP_FOR_RETRY. dag_id=workflow, task_id=Load, execution_date=20240308T000000, start_date=20250327T172933, end_date=20250327T172934
[2025-03-27T17:29:34.341+0000] {standard_task_runner.py:107} ERROR - Failed to execute job 132 for task Load (Task received SIGTERM signal; 1728)
[2025-03-27T17:29:34.396+0000] {process_utils.py:79} INFO - Process psutil.Process(pid=1728, status='terminated', exitcode=1, started='17:29:33') (1728) terminated with exit code 1
[2025-03-27T17:29:34.399+0000] {local_task_job_runner.py:234} INFO - Task exited with return code 143
[2025-03-27T17:29:35.539+0000] {taskinstance.py:3280} INFO - 0 downstream tasks scheduled from follow-on schedule check
