[2025-03-27T17:29:33.588+0000] {taskinstance.py:1956} INFO - Dependencies all met for dep_context=non-requeueable deps ti=<TaskInstance: workflow.Load scheduled__2024-03-07T00:00:00+00:00 [queued]>
[2025-03-27T17:29:33.609+0000] {taskinstance.py:1956} INFO - Dependencies all met for dep_context=requeueable deps ti=<TaskInstance: workflow.Load scheduled__2024-03-07T00:00:00+00:00 [queued]>
[2025-03-27T17:29:33.611+0000] {taskinstance.py:2170} INFO - Starting attempt 1 of 6
[2025-03-27T17:29:33.913+0000] {taskinstance.py:2191} INFO - Executing <Task(BashOperator): Load> on 2024-03-07 00:00:00+00:00
[2025-03-27T17:29:33.934+0000] {standard_task_runner.py:60} INFO - Started process 1729 to run task
[2025-03-27T17:29:33.942+0000] {standard_task_runner.py:87} INFO - Running: ['***', 'tasks', 'run', 'workflow', 'Load', 'scheduled__2024-03-07T00:00:00+00:00', '--job-id', '131', '--raw', '--subdir', 'DAGS_FOLDER/workflow.py', '--cfg-path', '/tmp/tmpn4xlusbq']
[2025-03-27T17:29:33.947+0000] {standard_task_runner.py:88} INFO - Job 131: Subtask Load
[2025-03-27T17:29:34.103+0000] {task_command.py:423} INFO - Running <TaskInstance: workflow.Load scheduled__2024-03-07T00:00:00+00:00 [running]> on host 77747a310b55
[2025-03-27T17:29:34.238+0000] {local_task_job_runner.py:121} ERROR - Received SIGTERM. Terminating subprocesses
[2025-03-27T17:29:34.252+0000] {process_utils.py:131} INFO - Sending 15 to group 1729. PIDs of all processes in the group: [1729]
[2025-03-27T17:29:34.257+0000] {process_utils.py:86} INFO - Sending the signal 15 to group 1729
[2025-03-27T17:29:34.258+0000] {taskinstance.py:2450} ERROR - Received SIGTERM. Terminating subprocesses.
[2025-03-27T17:29:34.260+0000] {subprocess.py:104} INFO - Sending SIGTERM signal to process group
[2025-03-27T17:29:34.284+0000] {taskinstance.py:2698} ERROR - Task failed with exception
Traceback (most recent call last):
  File "/home/airflow/.local/lib/python3.8/site-packages/airflow/models/taskinstance.py", line 2334, in _run_raw_task
    self._execute_task_with_callbacks(context, test_mode, session=session)
  File "/home/airflow/.local/lib/python3.8/site-packages/airflow/models/taskinstance.py", line 2469, in _execute_task_with_callbacks
    RenderedTaskInstanceFields.write(rtif)
  File "/home/airflow/.local/lib/python3.8/site-packages/airflow/utils/session.py", line 79, in wrapper
    return func(*args, session=session, **kwargs)
  File "/usr/local/lib/python3.8/contextlib.py", line 120, in __exit__
    next(self.gen)
  File "/home/airflow/.local/lib/python3.8/site-packages/airflow/utils/session.py", line 39, in create_session
    session.commit()
  File "/home/airflow/.local/lib/python3.8/site-packages/sqlalchemy/orm/session.py", line 1454, in commit
    self._transaction.commit(_to_root=self.future)
  File "/home/airflow/.local/lib/python3.8/site-packages/sqlalchemy/orm/session.py", line 832, in commit
    self._prepare_impl()
  File "/home/airflow/.local/lib/python3.8/site-packages/sqlalchemy/orm/session.py", line 811, in _prepare_impl
    self.session.flush()
  File "/home/airflow/.local/lib/python3.8/site-packages/sqlalchemy/orm/session.py", line 3449, in flush
    self._flush(objects)
  File "/home/airflow/.local/lib/python3.8/site-packages/sqlalchemy/orm/session.py", line 3589, in _flush
    transaction.rollback(_capture_exception=True)
  File "/home/airflow/.local/lib/python3.8/site-packages/sqlalchemy/util/langhelpers.py", line 70, in __exit__
    compat.raise_(
  File "/home/airflow/.local/lib/python3.8/site-packages/sqlalchemy/util/compat.py", line 211, in raise_
    raise exception
  File "/home/airflow/.local/lib/python3.8/site-packages/sqlalchemy/orm/session.py", line 3549, in _flush
    flush_context.execute()
  File "/home/airflow/.local/lib/python3.8/site-packages/sqlalchemy/orm/unitofwork.py", line 456, in execute
    rec.execute(self)
  File "/home/airflow/.local/lib/python3.8/site-packages/sqlalchemy/orm/unitofwork.py", line 630, in execute
    util.preloaded.orm_persistence.save_obj(
  File "/home/airflow/.local/lib/python3.8/site-packages/sqlalchemy/orm/persistence.py", line 245, in save_obj
    _emit_insert_statements(
  File "/home/airflow/.local/lib/python3.8/site-packages/sqlalchemy/orm/persistence.py", line 1097, in _emit_insert_statements
    c = connection._execute_20(
  File "/home/airflow/.local/lib/python3.8/site-packages/sqlalchemy/engine/base.py", line 1710, in _execute_20
    return meth(self, args_10style, kwargs_10style, execution_options)
  File "/home/airflow/.local/lib/python3.8/site-packages/sqlalchemy/sql/elements.py", line 334, in _execute_on_connection
    return connection._execute_clauseelement(
  File "/home/airflow/.local/lib/python3.8/site-packages/sqlalchemy/engine/base.py", line 1569, in _execute_clauseelement
    compiled_sql, extracted_params, cache_hit = elem._compile_w_cache(
  File "/home/airflow/.local/lib/python3.8/site-packages/sqlalchemy/sql/elements.py", line 515, in _compile_w_cache
    elem_cache_key = self._generate_cache_key()
  File "/home/airflow/.local/lib/python3.8/site-packages/sqlalchemy/util/langhelpers.py", line 1193, in oneshot
    result = fn(self, *args, **kw)
  File "/home/airflow/.local/lib/python3.8/site-packages/sqlalchemy/sql/traversals.py", line 342, in _generate_cache_key
    return HasCacheKey._generate_cache_key(self)
  File "/home/airflow/.local/lib/python3.8/site-packages/sqlalchemy/sql/traversals.py", line 325, in _generate_cache_key
    return CacheKey(key, bindparams)
  File "<string>", line 1, in __new__
  File "/home/airflow/.local/lib/python3.8/site-packages/airflow/models/taskinstance.py", line 2452, in signal_handler
    raise AirflowException("Task received SIGTERM signal")
airflow.exceptions.AirflowException: Task received SIGTERM signal
[2025-03-27T17:29:34.304+0000] {taskinstance.py:1138} INFO - Marking task as UP_FOR_RETRY. dag_id=workflow, task_id=Load, execution_date=20240307T000000, start_date=20250327T172933, end_date=20250327T172934
[2025-03-27T17:29:34.340+0000] {standard_task_runner.py:107} ERROR - Failed to execute job 131 for task Load (Task received SIGTERM signal; 1729)
[2025-03-27T17:29:34.399+0000] {process_utils.py:79} INFO - Process psutil.Process(pid=1729, status='terminated', exitcode=1, started='17:29:33') (1729) terminated with exit code 1
[2025-03-27T17:29:34.401+0000] {local_task_job_runner.py:234} INFO - Task exited with return code 143
[2025-03-27T17:29:35.537+0000] {taskinstance.py:3280} INFO - 0 downstream tasks scheduled from follow-on schedule check
